<?xml version="1.0" encoding="UTF-8"?>
<!DOCTYPE xml>
<sdf version="1.9">
  <model name="pusher">

    <!-- Joint to fix pusher to the world -->
    <joint name="base_joint" type="fixed">
      <parent>world</parent>
      <child>base</child>
    </joint>

    <!-- Pusher base -->
    <link name="base">
      <pose>0 -2.5 3 0 0 0</pose>
      <visual name="base_visual">
        <geometry>
          <box>
            <size>2 2 6</size>
          </box>
        </geometry>
        <material>
          <ambient>0.2 0.2 0.2 1</ambient>
          <diffuse>0.2 0.2 0.2 1</diffuse>
        </material>
      </visual>
    </link>

    <!-- Camera Holder -->
    <link name="holder_link">
      <pose relative_to="base">0 1.8 2.5 0 0 0</pose>
      <visual name="holder_link_visual">
        <geometry>
          <box>
            <size>1 1.8 0.25</size>
          </box>
        </geometry>
        <material>
          <ambient>0.2 0.2 0.2 1</ambient>
          <diffuse>0.2 0.2 0.2 1</diffuse>
        </material>
      </visual>
    </link>

    <joint name="holder_joint" type="fixed">
      <parent>base</parent>
      <child>holder_link</child>
    </joint>

    <!-- Camera Link -->
    <link name="camera_link">
      <pose relative_to="holder_link">0 0.55 -0.175 0 1.5708 1.5708</pose>
      <visual name="camera_link_visual">
        <geometry>
          <box>
            <size>0.1 0.5 0.25</size>
          </box>
        </geometry>
        <material>
          <ambient>0 0 0 1</ambient>
          <diffuse>0 0 0 1</diffuse>
        </material>
      </visual>
      <sensor name="camera_sensor" type="camera">
        <always_on>false</always_on>
        <visualize>true</visualize>
        <update_rate>30</update_rate>
        <topic>pusher/camera_raw</topic>
        <camera name="camera">
          <camera_info_topic>camera/camera_info</camera_info_topic>
          <horizontal_fov>1.037</horizontal_fov>
          <image>
            <width>320</width>
            <height>240</height>
            <format>R8G8B8</format>
          </image>
          <clip>
            <near>0.1</near>
            <far>10</far>
          </clip>
        </camera>
      </sensor>
    </link>

    <joint name="camera_joint" type="fixed">
      <parent>holder_link</parent>
      <child>camera_link</child>
    </joint>

    <!-- Rod to push the cubes -->
    <link name="rod">
      <pose relative_to="base">0 0.25 -1.4 0 0 0</pose>
      <visual name="rod_visual">
        <geometry>
          <box>
            <size>1.6 2 1</size>
          </box>
        </geometry>
        <material>
          <ambient>0.2 0.2 0.2 1</ambient>
          <diffuse>0.2 0.2 0.2 1</diffuse>
        </material>
      </visual>
      <collision name="rod_collision">
        <geometry>
          <box>
            <size>1.6 2 1</size>
          </box>
        </geometry>
      </collision>
    </link>

    <joint name="rod_joint" type="prismatic">
      <parent>base</parent>
      <child>rod</child>
      <axis>
        <xyz>0 1 0</xyz>
        <limit>
          <lower>0</lower>
          <upper>3</upper>
        </limit>
      </axis>
    </joint>

    <plugin filename="gz-sim-joint-position-controller-system" name="gz::sim::systems::JointPositionController">
      <joint_name>rod_joint</joint_name>
      <topic>pusher/position</topic>
      <p_gain>2000</p_gain>
      <i_gain>20</i_gain>
      <d_gain>100</d_gain>
      <cmd_max>10000</cmd_max>
      <cmd_mix>-10000</cmd_mix>
    </plugin>

    <plugin filename="gz-sim-joint-state-publisher-system" name="gz::sim::systems::JointStatePublisher">
      <joint_name>rod_joint</joint_name>
      <topic>pusher/state</topic>
    </plugin>

    <plugin filename="gz-sim-sensors-system" name="gz::sim::systems::Sensors">
      <render_engine>ogre2</render_engine>
    </plugin>
  </model>
</sdf>
